============================= test session starts ==============================
platform darwin -- Python 3.11.9, pytest-7.4.3, pluggy-1.6.0 -- /usr/local/bin/python3.11
cachedir: .pytest_cache
rootdir: /Users/a.kotenev/PycharmProjects/dev_exp_ai
configfile: pytest.ini
plugins: Faker-20.1.0, cov-4.1.0, asyncio-0.21.1, mock-3.12.0, anyio-3.7.1, docker-2.0.1
asyncio: mode=Mode.STRICT
collecting ... collected 177 items / 7 errors

==================================== ERRORS ====================================
_______________ ERROR collecting tests/test_e2e_comprehensive.py _______________
ImportError while importing test module '/Users/a.kotenev/PycharmProjects/dev_exp_ai/tests/test_e2e_comprehensive.py'.
Hint: make sure your test modules/packages have valid Python names.
Traceback:
/Library/Frameworks/Python.framework/Versions/3.11/lib/python3.11/importlib/__init__.py:126: in import_module
    return _bootstrap._gcd_import(name[level:], package, level)
tests/test_e2e_comprehensive.py:4: in <module>
    from app.main import app
app/main.py:43: in <module>
    from app.websocket import handle_websocket_connection
E   ImportError: cannot import name 'handle_websocket_connection' from 'app.websocket' (/Users/a.kotenev/PycharmProjects/dev_exp_ai/app/websocket.py)
____________ ERROR collecting tests/test_e2e_with_large_dataset.py _____________
ImportError while importing test module '/Users/a.kotenev/PycharmProjects/dev_exp_ai/tests/test_e2e_with_large_dataset.py'.
Hint: make sure your test modules/packages have valid Python names.
Traceback:
/Library/Frameworks/Python.framework/Versions/3.11/lib/python3.11/importlib/__init__.py:126: in import_module
    return _bootstrap._gcd_import(name[level:], package, level)
tests/test_e2e_with_large_dataset.py:18: in <module>
    from app.main import create_app
app/main.py:43: in <module>
    from app.websocket import handle_websocket_connection
E   ImportError: cannot import name 'handle_websocket_connection' from 'app.websocket' (/Users/a.kotenev/PycharmProjects/dev_exp_ai/app/websocket.py)
___________________ ERROR collecting tests/test_security.py ____________________
ImportError while importing test module '/Users/a.kotenev/PycharmProjects/dev_exp_ai/tests/test_security.py'.
Hint: make sure your test modules/packages have valid Python names.
Traceback:
/Library/Frameworks/Python.framework/Versions/3.11/lib/python3.11/importlib/__init__.py:126: in import_module
    return _bootstrap._gcd_import(name[level:], package, level)
tests/test_security.py:15: in <module>
    from app.main import app
app/main.py:43: in <module>
    from app.websocket import handle_websocket_connection
E   ImportError: cannot import name 'handle_websocket_connection' from 'app.websocket' (/Users/a.kotenev/PycharmProjects/dev_exp_ai/app/websocket.py)
________________ ERROR collecting tests/test_security_backup.py ________________
ImportError while importing test module '/Users/a.kotenev/PycharmProjects/dev_exp_ai/tests/test_security_backup.py'.
Hint: make sure your test modules/packages have valid Python names.
Traceback:
/Library/Frameworks/Python.framework/Versions/3.11/lib/python3.11/importlib/__init__.py:126: in import_module
    return _bootstrap._gcd_import(name[level:], package, level)
tests/test_security_backup.py:15: in <module>
    from app.main import app
app/main.py:43: in <module>
    from app.websocket import handle_websocket_connection
E   ImportError: cannot import name 'handle_websocket_connection' from 'app.websocket' (/Users/a.kotenev/PycharmProjects/dev_exp_ai/app/websocket.py)
_________________ ERROR collecting tests/test_vector_search.py _________________
ImportError while importing test module '/Users/a.kotenev/PycharmProjects/dev_exp_ai/tests/test_vector_search.py'.
Hint: make sure your test modules/packages have valid Python names.
Traceback:
/Library/Frameworks/Python.framework/Versions/3.11/lib/python3.11/importlib/__init__.py:126: in import_module
    return _bootstrap._gcd_import(name[level:], package, level)
tests/test_vector_search.py:18: in <module>
    from app.main import app
app/main.py:43: in <module>
    from app.websocket import handle_websocket_connection
E   ImportError: cannot import name 'handle_websocket_connection' from 'app.websocket' (/Users/a.kotenev/PycharmProjects/dev_exp_ai/app/websocket.py)
______________ ERROR collecting tests/integration/test_api_v1.py _______________
ImportError while importing test module '/Users/a.kotenev/PycharmProjects/dev_exp_ai/tests/integration/test_api_v1.py'.
Hint: make sure your test modules/packages have valid Python names.
Traceback:
/Library/Frameworks/Python.framework/Versions/3.11/lib/python3.11/importlib/__init__.py:126: in import_module
    return _bootstrap._gcd_import(name[level:], package, level)
tests/integration/test_api_v1.py:3: in <module>
    from app.main import create_app
app/main.py:43: in <module>
    from app.websocket import handle_websocket_connection
E   ImportError: cannot import name 'handle_websocket_connection' from 'app.websocket' (/Users/a.kotenev/PycharmProjects/dev_exp_ai/app/websocket.py)
______________ ERROR collecting tests/unit/test_api_endpoints.py _______________
ImportError while importing test module '/Users/a.kotenev/PycharmProjects/dev_exp_ai/tests/unit/test_api_endpoints.py'.
Hint: make sure your test modules/packages have valid Python names.
Traceback:
/Library/Frameworks/Python.framework/Versions/3.11/lib/python3.11/importlib/__init__.py:126: in import_module
    return _bootstrap._gcd_import(name[level:], package, level)
tests/unit/test_api_endpoints.py:8: in <module>
    from app.main import create_app
app/main.py:43: in <module>
    from app.websocket import handle_websocket_connection
E   ImportError: cannot import name 'handle_websocket_connection' from 'app.websocket' (/Users/a.kotenev/PycharmProjects/dev_exp_ai/app/websocket.py)
=========================== short test summary info ============================
ERROR tests/test_e2e_comprehensive.py
ERROR tests/test_e2e_with_large_dataset.py
ERROR tests/test_security.py
ERROR tests/test_security_backup.py
ERROR tests/test_vector_search.py
ERROR tests/integration/test_api_v1.py
ERROR tests/unit/test_api_endpoints.py
!!!!!!!!!!!!!!!!!!! Interrupted: 7 errors during collection !!!!!!!!!!!!!!!!!!!!
============================== 7 errors in 0.58s ===============================
